<?xml version="1.0" encoding="UTF-8"?>
<robot xmlns:xacro="http://www.ros.org/wiki/xacro">
   <xacro:macro name="omx_l" params="prefix">
   <xacro:property name="meshes_file_direction" value="package://open_manipulator_description/meshes/omx_l" />
      <link name="${prefix}link0" >
         <visual>
            <origin xyz="0 0 0" rpy="0 0 0" />
            <geometry>
               <mesh filename="${meshes_file_direction}/leader_01_base_roll.stl" scale="0.001 0.001 0.001" />
            </geometry>
            <material name="grey">
               <color rgba="0.2 0.2 0.2 1" />
            </material>
         </visual>
         <collision>
            <origin xyz="0 0 0" rpy="0 0 0" />
            <geometry>
               <mesh filename="${meshes_file_direction}/leader_01_base_roll.stl" scale="0.001 0.001 0.001" />
            </geometry>
            <material name="grey">
               <color rgba="0.2 0.2 0.2 1" />
            </material>
         </collision>
         <inertial>
            <origin xyz="-1.238633200e-02 -5.447235500e-03 1.744509700e-02" />
            <mass value="1.451075000e-01" />
            <inertia ixx="2.628250300e-04" ixy="-5.614281600e-06" ixz="7.685931300e-06"
            iyy="1.477645100e-04" iyz="1.937324800e-06"
            izz="3.204220800e-04" />
         </inertial>
      </link>
      <joint name="${prefix}joint1" type="revolute">
         <parent link="${prefix}link0" />
         <child link="${prefix}link1" />
         <origin xyz="-0.0095 0 0.0545" rpy="0 0 0" />
         <axis xyz="0 0 1" />
         <limit velocity="4.8" effort="1000" lower="${-pi*2.0}" upper="${pi*2.0}" />
         <dynamics damping="0.05" />
      </joint>
      <link name="${prefix}link1" >
         <visual>
            <origin xyz="0 0 0" rpy="0 0 0" />
            <geometry>
               <mesh filename="${meshes_file_direction}/leader_02_base_tilt_revised.stl" scale="0.001 0.001 0.001" />
            </geometry>
            <material name="grey">
               <color rgba="0.2 0.2 0.2 1" />
            </material>
         </visual>
         <collision>
            <origin xyz="0 0 0" rpy="0 0 0" />
            <geometry>
               <mesh filename="${meshes_file_direction}/leader_02_base_tilt_revised.stl" scale="0.001 0.001 0.001" />
            </geometry>
            <material name="grey">
               <color rgba="0.2 0.2 0.2 1" />
            </material>
         </collision>
         <inertial>
            <origin xyz="2.835039900e-05 2.751132400e-04 3.128092400e-02" />
            <mass value="2.527095100e-02" />
            <inertia ixx="4.407733000e-06" ixy="-5.103192400e-11" ixz="2.755486200e-09"
            iyy="4.218083500e-06" iyz="-1.016729100e-08"
            izz="1.868043300e-06" />
         </inertial>
      </link>
      <joint name="${prefix}joint2" type="revolute">
         <parent link="${prefix}link1" />
         <child link="${prefix}link2" />
         <origin xyz="0 0 0.042" rpy="0 0 0" />
         <axis xyz="0 1 0" />
         <limit velocity="4.8" effort="1000" lower="${-pi*2.0}" upper="${pi*2.0}" />
         <dynamics damping="0.1" />
      </joint>
      <link name="${prefix}link2" >
         <visual>
            <origin xyz="0 0 0" rpy="0 0 0" />
            <geometry>
               <mesh filename="${meshes_file_direction}/leader_03_middle_vertical.stl" scale="0.001 0.001 0.001" />
            </geometry>
            <material name="grey">
               <color rgba="0.2 0.2 0.2 1" />
            </material>
         </visual>
         <collision>
            <origin xyz="0 0 0" rpy="0 0 0" />
            <geometry>
               <mesh filename="${meshes_file_direction}/leader_03_middle_vertical.stl" scale="0.001 0.001 0.001" />
            </geometry>
            <material name="grey">
               <color rgba="0.2 0.2 0.2 1" />
            </material>
         </collision>
         <inertial>
            <origin xyz="1.424917700e-02 1.724114700e-04 6.876064000e-02" />
            <mass value="4.770623100e-02" />
            <inertia ixx="5.756046900e-05" ixy="-7.916400900e-08" ixz="-1.442184500e-05"
            iyy="6.581561500e-05" iyz="-5.987367400e-08"
            izz="1.652415800e-05" />
         </inertial>
      </link>
      <joint name="${prefix}joint3" type="revolute">
         <parent link="${prefix}link2" />
         <child link="${prefix}link3" />
          <origin xyz="0.0375 0 0.09" rpy="0 0 0" />
         <axis xyz="0 1 0" />
         <limit velocity="4.8" effort="1000" lower="${-pi*2.0}" upper="${pi*2.0}" />
         <dynamics damping="0.1" />
      </joint>
      <link name="${prefix}link3" >
         <visual>
            <origin xyz="0 0 0" rpy="0 0 0" />
            <geometry>
               <mesh filename="${meshes_file_direction}/leader_04_middle_horizontal.stl" scale="0.001 0.001 0.001" />
            </geometry>
            <material name="grey">
               <color rgba="0.2 0.2 0.2 1" />
            </material>
         </visual>
         <collision>
            <origin xyz="0 0 0" rpy="0 0 0" />
            <geometry>
               <mesh filename="${meshes_file_direction}/leader_04_middle_horizontal.stl" scale="0.001 0.001 0.001" />
            </geometry>
            <material name="grey">
               <color rgba="0.2 0.2 0.2 1" />
            </material>
         </collision>
         <inertial>
            <origin xyz="8.282742400e-02 1.724150100e-04 1.823923200e-04" />
            <mass value="4.770623100e-02" />
            <inertia ixx="5.604141500e-06" ixy="-1.407750000e-07" ixz="-4.627927600e-08"
            iyy="9.456674600e-05" iyz="1.755014700e-09"
            izz="9.723161700e-05" />
         </inertial>
      </link>
      <joint name="${prefix}joint4" type="revolute">
         <parent link="${prefix}link3" />
         <child link="${prefix}link4" />
         <origin xyz="0.1275 0 0" rpy="0 0 0" />
         <axis xyz="0 1 0" />
         <limit velocity="4.8" effort="1000" lower="${-pi*2.0}" upper="${pi*2.0}" />
         <dynamics damping="0.1" />
      </joint>
      <link name="${prefix}link4" >
         <visual>
            <origin xyz="0 0 0" rpy="0 0 0" />
            <geometry>
               <mesh filename="${meshes_file_direction}/leader_05_tip_roll.stl" scale="0.001 0.001 0.001" />
            </geometry>
            <material name="grey">
               <color rgba="0.2 0.2 0.2 1" />
            </material>
         </visual>
         <collision>
            <origin xyz="0 0 0" rpy="0 0 0" />
            <geometry>
               <mesh filename="${meshes_file_direction}/leader_05_tip_roll.stl" scale="0.001 0.001 0.001" />
            </geometry>
            <material name="grey">
               <color rgba="0.2 0.2 0.2 1" />
            </material>
         </collision>
         <inertial>
            <origin xyz="2.226281200e-02 6.543368700e-05 5.886435800e-03" />
            <mass value="3.043181200e-02" />
            <inertia ixx="5.235858000e-06" ixy="2.348720300e-08" ixz="-9.501811500e-07"
            iyy="7.464600400e-06" iyz="1.225658100e-09"
            izz="6.780770900e-06" />
         </inertial>
      </link>
      <joint name="${prefix}joint5" type="revolute">
         <parent link="${prefix}link4" />
         <child link="${prefix}link5" />
         <origin xyz="0.0287 0 0" rpy="0 0 0" />
         <axis xyz="1 0 0" />
         <limit velocity="4.8" effort="1000" lower="${-pi*2.0}" upper="${pi*2.0}" />
         <dynamics damping="0.1" />
      </joint>
      <link name="${prefix}link5" >
         <visual>
            <origin xyz="0 0 0" rpy="0 0 0" />
            <geometry>
               <mesh filename="${meshes_file_direction}/leader_06_tip_pan_revised.stl" scale="0.001 0.001 0.001" />
            </geometry>
            <material name="grey">
               <color rgba="0.2 0.2 0.2 1" />
            </material>
         </visual>
         <collision>
            <origin xyz="0 0 0" rpy="0 0 0" />
            <geometry>
               <mesh filename="${meshes_file_direction}/leader_06_tip_pan_revised.stl" scale="0.001 0.001 0.001" />
            </geometry>
            <material name="grey">
               <color rgba="0.2 0.2 0.2 1" />
            </material>
         </collision>
         <inertial>
            <origin xyz="3.612422300e-02 2.809335000e-04 2.357443900e-05" />
            <mass value="3.962965900e-02" />
            <inertia ixx="1.056164100e-05" ixy="7.001923500e-08" ixz="6.009266300e-06"
            iyy="2.169751100e-05" iyz="-9.883190500e-08"
            izz="1.515746000e-05" />
         </inertial>
      </link>
      <joint name="${prefix}gripper_joint_1" type="revolute">
         <parent link="${prefix}link5" />
         <child link="${prefix}link6" />
         <origin xyz="0.0298 0 0.0175" rpy="0 0 0" />
         <axis xyz="0 1 0" />
         <limit velocity="4.8" effort="1000" lower="${-pi*2.0}" upper="${pi*2.0}" />
         <dynamics damping="0.1" />
      </joint>
      <link name="${prefix}link6" >
         <visual>
            <origin xyz="0 0 0" rpy="0 0 0" />
            <geometry>
               <mesh filename="${meshes_file_direction}/leader_07_tip_grip.stl" scale="0.001 0.001 0.001" />
            </geometry>
            <material name="grey">
               <color rgba="0.2 0.2 0.2 1" />
            </material>
         </visual>
         <collision>
            <origin xyz="0 0 0" rpy="0 0 0" />
            <geometry>
               <mesh filename="${meshes_file_direction}/leader_07_tip_grip.stl" scale="0.001 0.001 0.001" />
            </geometry>
            <material name="grey">
               <color rgba="0.2 0.2 0.2 1" />
            </material>
         </collision>
         <inertial>
            <origin xyz="2.848595800e-02 3.991033600e-05 3.499505900e-04" />
            <mass value="1.961145500e-02" />
            <inertia ixx="3.344745100e-06" ixy="4.387081200e-08" ixz="-2.497067000e-07"
            iyy="9.040789400e-06" iyz="-3.092786900e-09"
            izz="1.102437500e-05" />
         </inertial>
      </link>
   </xacro:macro>
</robot>
