<?xml version="1.0" ?>
<!-- =================================================================================== -->
<!-- |    This document was autogenerated by xacro from omy_l100.urdf.xacro            | -->
<!-- |    EDITING THIS FILE BY HAND IS NOT RECOMMENDED                                 | -->
<!-- =================================================================================== -->
<robot name="omy_l100">
  <link name="world"/>
  <joint name="world_fixed" type="fixed">
    <parent link="world"/>
    <child link="link0"/>
    <origin rpy="0 0 0" xyz="0.0 0.0 0.0"/>
  </joint>
  <link name="link0">
    <visual>
      <origin rpy="0 0 0" xyz="0 0 0"/>
      <geometry>
        <mesh filename="package://open_manipulator_description/meshes/omy_l100/base_unit.stl" scale="0.001 0.001 0.001"/>
      </geometry>
      <material name="grey">
        <color rgba="0.2 0.2 0.2 1"/>
      </material>
    </visual>
    <collision>
      <origin rpy="0 0 0" xyz="0 0 0"/>
      <geometry>
        <mesh filename="package://open_manipulator_description/meshes/omy_l100/base_unit.stl" scale="0.001 0.001 0.001"/>
      </geometry>
    </collision>
    <inertial>
      <origin xyz="-4.344917500e-02 -3.992420300e-03 2.438889300e-02"/>
      <mass value="7.911750300e-01"/>
      <inertia ixx="2.177161200e-03" ixy="-2.140439100e-04" ixz="-4.154329400e-04" iyy="4.577143100e-03" iyz="4.333048800e-05" izz="5.734302500e-03"/>
    </inertial>
  </link>
  <joint name="joint1" type="revolute">
    <parent link="link0"/>
    <child link="link1"/>
    <origin rpy="0 0 0" xyz="0 0 0.094"/>
    <axis xyz="0 0 1"/>
    <limit effort="1" lower="-3.14159265359" upper="3.14159265359" velocity="4.8"/>
  </joint>
  <link name="link1">
    <visual>
      <origin rpy="0 0 0" xyz="0 0 0"/>
      <geometry>
        <mesh filename="package://open_manipulator_description/meshes/omy_l100/link1.stl" scale="0.001 0.001 0.001"/>
      </geometry>
      <material name="grey">
        <color rgba="0.2 0.2 0.2 1"/>
      </material>
    </visual>
    <collision>
      <origin rpy="0 0 0" xyz="0 0 0"/>
      <geometry>
        <mesh filename="package://open_manipulator_description/meshes/omy_l100/link1.stl" scale="0.001 0.001 0.001"/>
      </geometry>
    </collision>
    <inertial>
      <origin xyz="-1.509477700e-02 -2.915253100e-03 -5.802932700e-04"/>
      <mass value="1.979262000e-01"/>
      <inertia ixx="6.236522600e-05" ixy="-2.338179800e-07" ixz="3.416491000e-07" iyy="9.434229600e-05" iyz="3.348362300e-07" izz="8.338957000e-05"/>
    </inertial>
  </link>
  <joint name="joint2" type="revolute">
    <parent link="link1"/>
    <child link="link2"/>
    <origin rpy="0 0 0" xyz="0 -0.0525 0"/>
    <axis xyz="0 1 0"/>
    <limit effort="1" lower="-3.14159265359" upper="3.14159265359" velocity="4.8"/>
  </joint>
  <link name="link2">
    <visual>
      <origin rpy="0 0 0" xyz="0 0 0"/>
      <geometry>
        <mesh filename="package://open_manipulator_description/meshes/omy_l100/link2.stl" scale="0.001 0.001 0.001"/>
      </geometry>
      <material name="grey">
        <color rgba="0.2 0.2 0.2 1"/>
      </material>
    </visual>
    <collision>
      <origin rpy="0 0 0" xyz="0 0 0"/>
      <geometry>
        <mesh filename="package://open_manipulator_description/meshes/omy_l100/link2.stl" scale="0.001 0.001 0.001"/>
      </geometry>
    </collision>
    <inertial>
      <origin xyz="-6.650923500e-05 2.244270300e-03 1.334962000e-01"/>
      <mass value="4.954724200e-01"/>
      <inertia ixx="6.398168100e-03" ixy="-7.395467200e-08" ixz="-1.959389300e-08" iyy="6.336367500e-03" iyz="8.810889200e-08" izz="1.470119400e-04"/>
    </inertial>
  </link>
  <joint name="joint3" type="revolute">
    <parent link="link2"/>
    <child link="link3"/>
    <origin rpy="0 0 0" xyz="0 0 0.2658"/>
    <axis xyz="0 1 0"/>
    <limit effort="1" lower="-3.14159265359" upper="3.14159265359" velocity="4.8"/>
  </joint>
  <link name="link3">
    <visual>
      <origin rpy="0 0 0" xyz="0 0 0"/>
      <geometry>
        <mesh filename="package://open_manipulator_description/meshes/omy_l100/link3.stl" scale="0.001 0.001 0.001"/>
      </geometry>
      <material name="grey">
        <color rgba="0.2 0.2 0.2 1"/>
      </material>
    </visual>
    <collision>
      <origin rpy="0 0 0" xyz="0 0 0"/>
      <geometry>
        <mesh filename="package://open_manipulator_description/meshes/omy_l100/link3.stl" scale="0.001 0.001 0.001"/>
      </geometry>
    </collision>
    <inertial>
      <origin xyz="-1.742877100e-04 4.972386500e-02 1.240044900e-01"/>
      <mass value="9.866013000e-02"/>
      <inertia ixx="6.461091100e-04" ixy="2.274496100e-08" ixz="9.825297400e-07" iyy="6.427102200e-04" iyz="-1.022461900e-05" izz="1.291516000e-05"/>
    </inertial>
  </link>
  <joint name="joint4" type="revolute">
    <parent link="link3"/>
    <child link="link4"/>
    <origin rpy="0 0 0" xyz="0 0.0525 0.222"/>
    <axis xyz="0 1 0"/>
    <limit effort="1" lower="-3.14159265359" upper="3.14159265359" velocity="4.8"/>
  </joint>
  <link name="link4">
    <visual>
      <origin rpy="0 0 0" xyz="0 0 0"/>
      <geometry>
        <mesh filename="package://open_manipulator_description/meshes/omy_l100/link4.stl" scale="0.001 0.001 0.001"/>
      </geometry>
      <material name="grey">
        <color rgba="0.2 0.2 0.2 1"/>
      </material>
    </visual>
    <collision>
      <origin rpy="0 0 0" xyz="0 0 0"/>
      <geometry>
        <mesh filename="package://open_manipulator_description/meshes/omy_l100/link4.stl" scale="0.001 0.001 0.001"/>
      </geometry>
    </collision>
    <inertial>
      <origin xyz="2.692126300e-05 -3.545546100e-02 7.576592300e-04"/>
      <mass value="2.668720000e-02"/>
      <inertia ixx="4.944019900e-06" ixy="-2.920029800e-09" ixz="1.343867900e-09" iyy="2.256703500e-06" iyz="1.488289400e-07" izz="4.478355500e-06"/>
    </inertial>
  </link>
  <joint name="joint5" type="revolute">
    <parent link="link4"/>
    <child link="link5"/>
    <origin rpy="0 0 0" xyz="0 -0.046 0"/>
    <axis xyz="0 0 1"/>
    <limit effort="1" lower="-3.14159265359" upper="3.14159265359" velocity="4.8"/>
  </joint>
  <link name="link5">
    <visual>
      <origin rpy="0 0 0" xyz="0 0 0"/>
      <geometry>
        <mesh filename="package://open_manipulator_description/meshes/omy_l100/link5.stl" scale="0.001 0.001 0.001"/>
      </geometry>
      <material name="grey">
        <color rgba="0.2 0.2 0.2 1"/>
      </material>
    </visual>
    <collision>
      <origin rpy="0 0 0" xyz="0 0 0"/>
      <geometry>
        <mesh filename="package://open_manipulator_description/meshes/omy_l100/link5.stl" scale="0.001 0.001 0.001"/>
      </geometry>
    </collision>
    <inertial>
      <origin xyz="-2.692126300e-05 -7.576592300e-04 3.395546100e-02"/>
      <mass value="2.668720000e-02"/>
      <inertia ixx="4.944019900e-06" ixy="1.343867900e-09" ixz="-2.920029800e-09" iyy="4.478355500e-06" iyz="1.488289400e-07" izz="2.256703500e-06"/>
    </inertial>
  </link>
  <joint name="joint6" type="revolute">
    <parent link="link5"/>
    <child link="link6"/>
    <origin rpy="0 0 0" xyz="0 0 0.0445"/>
    <axis xyz="0 1 0"/>
    <limit effort="1" lower="-3.14159265359" upper="3.14159265359" velocity="4.8"/>
  </joint>
  <link name="link6">
    <visual>
      <origin rpy="0 0 0" xyz="0 0 0"/>
      <geometry>
        <mesh filename="package://open_manipulator_description/meshes/omy_l100/link6.stl" scale="0.001 0.001 0.001"/>
      </geometry>
      <material name="grey">
        <color rgba="0.2 0.2 0.2 1"/>
      </material>
    </visual>
    <collision>
      <origin rpy="0 0 0" xyz="0 0 0"/>
      <geometry>
        <mesh filename="package://open_manipulator_description/meshes/omy_l100/link6.stl" scale="0.001 0.001 0.001"/>
      </geometry>
    </collision>
    <inertial>
      <origin xyz="3.756721200e-03 -7.729958800e-02 -3.207961700e-02"/>
      <mass value="1.091269900e-01"/>
      <inertia ixx="2.456516600e-04" ixy="1.956697100e-05" ixz="-6.407940700e-06" iyy="1.258115200e-04" iyz="-1.691115400e-06" izz="1.459343600e-04"/>
    </inertial>
  </link>
  <joint name="rh_r1_joint" type="revolute">
    <parent link="link6"/>
    <child link="link7"/>
    <origin rpy="0 0 0" xyz="0 -0.125 -0.0255"/>
    <axis xyz="1 0 0"/>
    <limit effort="1" lower="-3.14159265359" upper="3.14159265359" velocity="4.8"/>
  </joint>
  <link name="link7">
    <visual>
      <origin rpy="0 0 0" xyz="0 0 0"/>
      <geometry>
        <mesh filename="package://open_manipulator_description/meshes/omy_l100/link7.stl" scale="0.001 0.001 0.001"/>
      </geometry>
      <material name="grey">
        <color rgba="0.2 0.2 0.2 1"/>
      </material>
    </visual>
    <collision>
      <origin rpy="0 0 0" xyz="0 0 0"/>
      <geometry>
        <mesh filename="package://open_manipulator_description/meshes/omy_l100/link7.stl" scale="0.001 0.001 0.001"/>
      </geometry>
    </collision>
    <inertial>
      <origin xyz="-2.635467700e-04 -2.054786700e-03 -8.785326800e-03"/>
      <mass value="4.060915900e-03"/>
      <inertia ixx="7.509344100e-07" ixy="2.199112900e-09" ixz="9.402416300e-09" iyy="5.484008000e-07" iyz="-9.942781800e-08" izz="2.396226600e-07"/>
    </inertial>
  </link>
</robot>
