<?xml version="1.0" encoding="UTF-8"?>
<robot xmlns:xacro="http://www.ros.org/wiki/xacro">
   <xacro:macro name="omx_f" params="prefix">
      <link name="${prefix}link0" />
      <joint name="${prefix}joint1" type="revolute">
         <parent link="${prefix}link0" />
         <child link="${prefix}link1" />
         <origin xyz="0 0 0" rpy="0 0 0" />
         <axis xyz="0 0 1" />
         <limit velocity="4.8" effort="1000" lower="${-pi*2.0}" upper="${pi*2.0}" />
         <dynamics damping="0.05" />
      </joint>
      <link name="${prefix}link1" />
      <joint name="${prefix}joint2" type="revolute">
         <parent link="${prefix}link1" />
         <child link="${prefix}link2" />
         <origin xyz="0 0 0" rpy="0 0 0" />
         <axis xyz="0 1 0" />
         <limit velocity="4.8" effort="1000" lower="${-pi*2.0}" upper="${pi*2.0}" />
         <dynamics damping="0.1" />
      </joint>
      <link name="${prefix}link2" />
      <joint name="${prefix}joint3" type="revolute">
         <parent link="${prefix}link2" />
         <child link="${prefix}link3" />
          <origin xyz="0 0 0" rpy="0 0 0" />
         <axis xyz="0 1 0" />
         <limit velocity="4.8" effort="1000" lower="${-pi*2.0}" upper="${pi*2.0}" />
         <dynamics damping="0.1" />
      </joint>
      <link name="${prefix}link3" />
      <joint name="${prefix}joint4" type="revolute">
         <parent link="${prefix}link3" />
         <child link="${prefix}link4" />
         <origin xyz="0 0 0" rpy="0 0 0" />
         <axis xyz="0 1 0" />
         <limit velocity="4.8" effort="1000" lower="${-pi*2.0}" upper="${pi*2.0}" />
         <dynamics damping="0.1" />
      </joint>
      <link name="${prefix}link4" />
      <joint name="${prefix}joint5" type="revolute">
         <parent link="${prefix}link4" />
         <child link="${prefix}link5" />
         <origin xyz="0 0 0" rpy="0 0 0" />
         <axis xyz="0 0 1" />
         <limit velocity="4.8" effort="1000" lower="${-pi*2.0}" upper="${pi*2.0}" />
         <dynamics damping="0.1" />
      </joint>
      <link name="${prefix}link5" />
      <joint name="${prefix}joint6" type="revolute">
         <parent link="${prefix}link5" />
         <child link="${prefix}link6" />
         <origin xyz="0 0 0" rpy="0 0 0" />
         <axis xyz="0 1 0" />
         <limit velocity="4.8" effort="1000" lower="${-pi*2.0}" upper="${pi*2.0}" />
         <dynamics damping="0.1" />
      </joint>
      <link name="${prefix}link6" />
      <joint name="${prefix}end_effector_flange_joint" type="fixed">
         <parent link="${prefix}link6" />
         <child link="${prefix}link7" />
         <origin xyz="0 0 0" rpy="0 0 0" />
      </joint>
      <link name="${prefix}link7" /> 
   </xacro:macro>
</robot>

